<?xml version="1.0"?>
<robot xmlns:xacro="http://www.ros.org/wiki/xacro" name="robotino">

  <xacro:include filename="$(find xarm_description)/urdf/xarm6/xarm6.urdf.xacro"/>

  <!-- ******************** Properties ******************** -->
  <xacro:property name="mesh_scale" value="0.01 0.01 0.01"/>
  <xacro:property name="wheel_mesh" value="package://robotino_description/model/Robotino3_SplitWheel.dae"/>
  <xacro:property name="body_mesh" value="package://robotino_description/model/Robotino3_SplitMain_NoCamera.dae"/>
  <xacro:property name="tower_mesh" value="package://robotino_description/model/Robotino3_Platform.dae"/>
  <xacro:property name="hokuyo_mesh" value="package://robotino_description/meshes/sensors/hokuyo.dae"/>
  <xacro:property name="kinect_mesh" value="package://robotino_description/meshes/sensors/kinect.dae"/>

  <!-- ******************** Macros ******************** -->

  <xacro:macro name="wheel_link" params="index xyz rpy">
    <link name="wheel${index}_link">
      <visual>
        <origin xyz="0 0 0" rpy="0 0 0"/>
        <geometry>
          <mesh filename="${wheel_mesh}" scale="${mesh_scale}"/>
        </geometry>
      </visual>
      <collision>
        <origin xyz="0 0 0" rpy="0 0 0"/>
        <geometry>
          <mesh filename="${wheel_mesh}" scale="${mesh_scale}"/>
        </geometry>
      </collision>
    </link>
    <joint name="wheel${index}_joint" type="continuous">
      <parent link="base_link"/>
      <child link="wheel${index}_link"/>
      <origin xyz="${xyz}" rpy="${rpy}"/>
      <axis xyz="0 1 0"/>
    </joint>
  </xacro:macro>

  <!-- ******************** Base ******************** -->
  <link name="base_link">
    <visual>
      <origin xyz="0 0 0.035" rpy="0 0 1.5707"/>
      <geometry>
        <mesh filename="${body_mesh}" scale="${mesh_scale}"/>
      </geometry>
    </visual>
    <collision>
      <origin xyz="0 0 0.035" rpy="0 0 1.5707"/>
      <geometry>
        <mesh filename="${body_mesh}" scale="${mesh_scale}"/>
      </geometry>
    </collision>
  </link>

  <!-- ******************** Wheel ******************** -->
  <xacro:wheel_link index="0" xyz="-0.1825 -0.0001 0.059154" rpy="0 0 1.570796"/>
  <xacro:wheel_link index="1" xyz="0.090625 -0.157067 0.059154" rpy="0 0 3.665191"/>
  <xacro:wheel_link index="2" xyz="0.090625 0.156867 0.059154" rpy="0 0 -0.523599"/>

  <!-- ******************** Tower ******************** -->
  <link name="tower_link">
    <visual>
      <origin xyz="0 0 0" rpy="0 0 0"/>
      <geometry>
        <mesh filename="${tower_mesh}" scale="0.009 0.009 0.009"/>
      </geometry>
    </visual>
    <collision>
      <origin xyz="0 0 0" rpy="0 0 0"/>
      <geometry>
        <mesh filename="${tower_mesh}" scale="0.009 0.009 0.009"/>
      </geometry>
    </collision>
  </link>

  <joint name="tower_joint" type="fixed">
    <parent link="base_link"/>
    <child link="tower_link"/>
    <origin xyz="0 0 0.06" rpy="0 0 1.5707"/>
  </joint>

  <!-- ******************** Platform link ******************** -->
  <link name="platform_link">
 
  </link>

  <joint name="platform_joint" type="fixed">
    <parent link="base_link"/>
    <child link="platform_link"/>
    <origin xyz="0 0 0.76" rpy="0 0 0"/>
  </joint>  

  <!-- ******************** Hokuyo ******************** -->
  <link name="laser_link">
    <visual>
      <origin xyz="0 0 -0.055" rpy="0 0 1.57"/>
      <geometry>
        <mesh filename="${hokuyo_mesh}" scale="${mesh_scale}"/>
      </geometry>
    </visual>
  </link>

  <joint name="base_to_hokuyo" type="fixed">
    <parent link="base_link"/>
    <child link="laser_link"/>
    <origin xyz="0.07 0.0 0.28" rpy="0 0 0"/>
  </joint>

  <!-- Soporte fijo del Kinect -->
<link name="kinect_base_link"/>

<joint name="platform_to_kinect_base" type="fixed">
  <parent link="platform_link"/>
  <child link="kinect_base_link"/> 
  <origin xyz="0.17 0 0.09" rpy="0 0 0"/>
</joint>

<!-- Eje móvil del motor del Kinect -->
<link name="camera_link">
  <visual>
    <origin xyz="0 0 0" rpy="0 0 1.57"/>
    <geometry>
      <mesh filename="${kinect_mesh}" scale="1 1 1"/>
    </geometry>
  </visual>
</link>

<joint name="kinect_tilt_joint" type="revolute">
  <parent link="kinect_base_link"/>
  <child link="camera_link"/>
  <origin xyz="0 0 0" rpy="0 0 0"/>
  <axis xyz="0 1 0"/> <!-- eje de inclinación -->
  <limit lower="${-0.541}" upper="${0.541}" effort="1.0" velocity="1.0"/>
</joint>


<!-- ***************** Manipulator ****************-->
  <xacro:property name="use_xacro_load_yaml" value="false"/>

  <xacro:xarm6_urdf
    prefix="xarm_"
  
  />

  <!-- Fixed joint between robotino and arm base -->
  <joint name="robotino_to_xarm_mount" type="fixed">
    <parent link="platform_link"/>
    <child link="xarm_link0"/>
    <origin xyz="0 0 0.35" rpy="0 0 0"/> <!-- Ajusta la altura según montaje real -->
  </joint>

<!--<xacro:property name="is_ros2" value="false"/>
<xacro:property name="use_xacro_load_yaml" value="false"/>
<xacro:include filename="$(find xarm_description)/urdf/common/common.link.xacro" />
<xacro:common_link_visual mesh_path="$(find xarm_description)/meshes/xarm6" />

 <xacro:xarm6_robot
    prefix="xarm_"
    limited="false"
    velocity_control="false"
    add_gripper="false"
    add_bio_gripper="false"
    model_num="0"
    inertial_params_filename=""
    kinematics_params_filename=""
  />

  <joint name="platform_to_xarm" type="fixed">
    <parent link="platform_link"/>
    <child link="xarm_link_base"/>
    <origin xyz="0 0 0" rpy="0 0 0"/>
  </joint>-->
  
</robot>